<?xml version='1.0'?>
<robot name="robotic_arm">

    <!-- Base Link -->
    <link name="base_link">
        <visual>
            <origin xyz="0 0 1" rpy="0 0 0" />
            <geometry>
                <cylinder length="2" radius="0.1" />
            </geometry>
        </visual>
    </link>
    
    <!-- Link 1 -->
    <link name="Link 1">
        <visual>
            <origin xyz="0 0.5 0" rpy="-1.57 0 0" />
            <geometry>
                <cylinder length="1" radius="0.1" />
            </geometry>
        </visual>
    </link>
    <joint name="joint 1" type="revolute">
    	<parent link="base_link"/>
    	<child link="Link 1"/>
    	<origin xyz="0 0 2" rpy="0 0 0" />
    	<limit effort="1000.0" lower="0.0" upper="0.548" velocity="0.5"/>
    	<axis xyz="1 0 0" />
    </joint>
    
    <!-- Link 2 -->
    <link name="Link 2">
        <visual>
            <origin xyz="0 .5 0" rpy="1.57 0 0" />
            <geometry>
                <cylinder length="1" radius="0.1" />
            </geometry>
        </visual>
    </link>
    <joint name="joint 2" type="continuous">
    	<parent link="Link 1"/>
    	<child link="Link 2"/>
    	<origin xyz="0 1 0" rpy="0 0 0" />
    	<axis xyz="0 1 0" />
    </joint>
    
        <!-- Link 3 -->
    <link name="Link 3">
        <visual>
            <origin xyz="0 0 -0.5" rpy="0 0 0" />
            <geometry>
                <cylinder length="1" radius="0.1" />
            </geometry>
        </visual>
    </link>
    <joint name="joint 3" type="fixed">
    	<parent link="Link 2"/>
    	<child link="Link 3"/>
    	<origin xyz="0 1 0" rpy="0 0 0" />
    	<axis xyz="0 0 0" />
    </joint>
    
        <!-- Link 4 -->
    <link name="Link 4">
        <visual>
            <origin xyz="0 0.5 0 " rpy="1.57 0 0" />
            <geometry>
                <cylinder length="1" radius="0.1" />
            </geometry>
        </visual>
    </link>
    <joint name="joint 4" type="fixed">
    	<parent link="Link 3"/>
    	<child link="Link 4"/>
    	<origin xyz="0 0 -1" rpy="0 0 0" />
    	<axis xyz="0 0 0" />
    </joint>
    
        <!-- Link 5 -->
    <link name="Link 5">
        <visual>
            <origin xyz="0 0.5 0" rpy="1.57 0 0" />
            <geometry>
                <cylinder length="1" radius="0.1" />
            </geometry>
        </visual>
    </link>
    <joint name="joint 5" type="continuous">
    	<parent link="Link 4"/>
    	<child link="Link 5"/>
    	<origin xyz="0 1 0" rpy="0 0 0" />
    	<axis xyz="1 0 0" />
    </joint>
    
        <!-- Link 6 -->
    <link name="Link 6">
        <visual>
            <origin xyz="0 0 0.5" rpy="0 0 0" />
            <geometry>
                <cylinder length="1" radius="0.1" />
            </geometry>
        </visual>
    </link>
    <joint name="joint 6" type="revolute">
    	<parent link="Link 5"/>
    	<child link="Link 6"/>
    	<origin xyz="0 1 0" rpy="0 0 0" />
    	<limit effort="1000.0" lower="0.0" upper="0.548" velocity="0.5"/>
    	<axis xyz="0 0 1" />
    </joint>
    
</robot>
